Workbook

Sheet Data
A1: Crocs Inc. --- Historical Financial Data
A2: $ millions
B3: 2022 | C3: 2023 | D3: 2024 | E3: 2025
A5: Income Statement
A6: Revenue | B6: 3554.99 | C6: 3962.35 | D6: 4102.11 | E6: 4040.65
A7: Operating Income (EBIT) | B7: 850.76 | C7: 1036.78 | D7: 1021.91 | E7: 149.52
A8: Income Before Taxes | B8: 718.51 | C8: 876.27 | D8: 910.59 | E8: 72.98
A9: Income Tax Expense | B9: 178.35 | C9: 83.71 | D9: -39.49 | E9: 154.18
A11: Cash Flow Statement
A12: Depreciation & Amortization | B12: 39.23 | C12: 54.3 | D12: 69.84 | E12: 79.28
A13: Capital Expenditures | B13: -104.19 | C13: -115.63 | D13: -69.35 | E13: -51.23
A15: Balance Sheet
A16: Cash & Cash Equivalents | B16: 191.63 | C16: 149.29 | D16: 180.49 | E16: 130.35
A17: Total Debt & Lease Liabilities ($M) | B17: 2594.96 | C17: 1996.36 | D17: 1701.3 | E17: 1613.85
A18: Current Assets | B18: 1025.98 | C18: 910.7 | D18: 872.27 | E18: 885.88
A19: Current Operating Liabilities | B19: =B20-B21 -> 559.45 | C19: =C20-C21 -> 612.7 | D19: =D20-D21 -> 671.66 | E19: =E20-E21 -> 614.36
A20: Total Current Liabilites | B20: 641.27 | C20: 698.3 | D20: 740.21 | E20: 700.13
A21: Current Debt & Lease Obligations | B21: 81.82 | C21: 85.6 | D21: 68.55 | E21: 85.77
A23: Crocs Brand Revenue | E23: 3325.807
A24: HEYDUDE Brand Revenue | E24: 714.84
A26: Asset Impairments | E26: 738.1
A28: Operating Working Capital Breakdown | C28: 2023 ($M) | D28: 2024 ($M) | E28: 2025 ($M)
A30: Accounts Receivable | C30: 305.747 | D30: 257.657 | E30: 278.191
A31: Inventory | C31: 385.054 | D31: 356.254 | E31: 368.687
A32: Other Receivables | C32: 21.071 | D32: 22.204 | E32: 22.082
A33: Prepaid Expenses & Other Assets | C33: 45.129 | D33: 51.623 | E33: 53.787
A34: Accounts Payable | C34: 260.978 | D34: 264.901 | E34: 266.09
A35: Accrued Expenses & Other Liabilities | C35: 285.771 | D35: 298.068 | E35: 300.959
A37: Operating Net Working Capital | C37: =SUM(C30:C33)-SUM(C34:C35) -> 210.252 | D37: =SUM(D30:D33)-SUM(D34:D35) -> 124.769 | E37: =SUM(E30:E33)-SUM(E34:E35) -> 155.698
A38: Operating NWC % of Revenue | C38: =C37/C6 -> 0.05306245 | D38: =D37/D6 -> 0.03041581 | E38: =E37/E6 -> 0.038532909
A40: Source: Crocs Inc. FY2022-FY2025 Form 10-K filings and company earnings releases, USD millions unless otherwised noted.
A41: `
A43: Cash & Cash Equivalents ($M) | B43: 170.276
A44: Interest-Bearing Debt ($M) | B44: 1334
A46: 2026 Interim Cash Flow Data, Six Months Ended June 30, 2026
A48: Operating Cash Flow ($M) | B48: 270.768
A49: Capital Expenditures ($M) | B49: -38.729
A50: Free Cash Flow ($M) | B50: =SUM(B48:B49) -> 232.039
A52: H1 2026 FCFF Reconciliation
A54: Operating Income (EBIT) ($M) | B54: 486.522
...

Sheet Assumptions
A1: Crocs Inc -- Financial Assumptions
A2: Historical Financial Ratios
B4: 2023 | C4: 2024 | D4: 2025
A6: Revenue Growth | B6: =Data!C6/Data!B6-1 -> 0.11458823 | C6: =Data!D6/Data!C6-1 -> 0.035271998 | D6: =Data!E6/Data!D6-1 -> -0.014982533
A7: EBIT Margin | B7: =Data!C7/Data!C6 -> 0.26165785 | C7: =Data!D7/Data!D6 -> 0.24911814 | D7: =Data!E7/Data!E6 -> 0.037003947
A8: Effective Tax Rate | B8: =Data!C9/Data!C8 -> 0.095529917 | C8: =Data!D9/Data!D8 -> -0.043367487 | D8: =Data!E9/Data!E8 -> 2.1126336
A9: D&A % of Revenue | B9: =Data!C12/Data!C6 -> 0.013703989 | C9: =Data!D12/Data!D6 -> 0.017025384 | D9: =Data!E12/Data!E6 -> 0.019620606
A10: CapEx % of Revenue | B10: =Data!C13/Data!C6 -> -0.029182177 | C10: =Data!D13/Data!D6 -> -0.016905934 | D10: =Data!E13/Data!E6 -> -0.012678653
A11: Net Working Capital | B11: =Data!C37 -> 210.252 | C11: =Data!D37 -> 124.769 | D11: =Data!E37 -> 155.698
A12: NWC % of Revenue | B12: =B11/Data!C6 -> 0.05306245 | C12: =C11/Data!D6 -> 0.03041581 | D12: =D11/Data!E6 -> 0.038532909
A15: Forecast Assumptions
B17: 2026 | C17: 2027 | D17: 2028 | E17: 2029 | F17: 2030
A19: Revenue Growth | B19: =C33/B33-1 -> 0.015269826 | C19: =D33/C33-1 -> 0.024929282 | D19: =E33/D33-1 -> 0.026701745 | E19: =F33/E33-1 -> 0.027566549 | F19: =G33/F33-1 -> 0.028397539
A20: EBIT Margin | B20: 0.22 | C20: 0.22 | D20: 0.2225 | E20: 0.225 | F20: 0.225
A21: Tax Rate | B21: 0.23 | C21: 0.23 | D21: 0.23 | E21: 0.23 | F21: 0.23
A22: D&A % of Revenue | B22: =$D$9 -> 0.019620606 | C22: =$D$9 -> 0.019620606 | D22: =$D$9 -> 0.019620606 | E22: =$D$9 -> 0.019620606 | F22: =$D$9 -> 0.019620606
A23: CapEx % of Revenue | B23: =B50/C33 -> -0.018282218 | C23: -0.019 | D23: -0.02 | E23: -0.0205 | F23: -0.021
A24: NWC % of Revenue | B24: =AVERAGE(C12:D12) -> 0.03447436 | C24: =$B$24 -> 0.03447436 | D24: =$B$24 -> 0.03447436 | E24: =$B$24 -> 0.03447436 | F24: =$B$24 -> 0.03447436
A27: Brand-Level Revenue Forecast
B29: 2025 | C29: 2026 | D29: 2027 | E29: 2028 | F29: 2029 | G29: 2030
A31: Crocs Brand Revenue | B31: =Data!E23 -> 3325.807 | C31: =B31*(1+C35) -> 3408.9522 | D31: =C31*(1+D35) -> 3511.2207 | E31: =D31*(1+E35) -> 3616.5574 | F31: =E31*(1+F35) -> 3725.0541 | G31: =F31*(1+G35) -> 3836.8057
A32: HEYDUDE Revenue | B32: =Data!E24 -> 714.84 | C32: =B32*(1+C36) -> 693.3948 | D32: =C32*(1+D36) -> 693.3948 | E32: =D32*(1+E36) -> 700.32875 | F32: =E32*(1+F36) -> 710.83368 | G32: =F32*(1+G36) -> 725.05035
A33: Total Revenue | B33: =SUM(B31:B32) -> 4040.647 | C33: =SUM(C31:C32) -> 4102.347 | D33: =SUM(D31:D32) -> 4204.6155 | E33: =SUM(E31:E32) -> 4316.8861 | F33: =SUM(F31:F32) -> 4435.8878 | G33: =SUM(G31:G32) -> 4561.8561
A35: Crocs Brand Growth | C35: 0.025 | D35: 0.03 | E35: 0.03 | F35: 0.03 | G35: 0.03
A36: HEYDUDE Brand Growth | C36: -0.03 | D36: 0 | E36: 0.01 | F36: 0.015 | G36: 0.02
A39: 2025 EBIT Normalization
A41: Asset Impairments ($M) | B41: =Data!E26 -> 738.1
A42: Impairment-Adjusted EBIT ($M) | B42: =Data!E7+Assumptions!B41 -> 887.62
A43: Adjusted EBIT Margin | B43: =B42/Data!E6 -> 0.21967258
A46: 2026 CapEx Guidance
A48: Low Spending Estimate ($M) | B48: -70
A49: High Spending Estimate ($M) | B49: -80
A50: Midpoint CapEx ($M) | B50: =AVERAGE(B48,B49) -> -75
A52: Sources : Crocs FY2025 financial results, FY2026 management guidance, and historical financial statements. Forecast assumptions are analyst estimates unless otherwise noted.

Sheet Income Statement
A1: Crocs Inc. -- Projected Income Statement
A2: USD Millions ($M)
B4: 2025 | C4: 2026 | D4: 2027 | E4: 2028 | F4: 2029 | G4: 2030
A6: Revenue | B6: =Data!E6 -> 4040.65 | C6: =Assumptions!C33 -> 4102.347 | D6: =Assumptions!D33 -> 4204.6155 | E6: =Assumptions!E33 -> 4316.8861 | F6: =Assumptions!F33 -> 4435.8878 | G6: =Assumptions!G33 -> 4561.8561
A7: Revenue Growth | B7: =Assumptions!D6 -> -0.014982533 | C7: =C6/B6-1 -> 0.015269072 | D7: =D6/C6-1 -> 0.024929282 | E7: =E6/D6-1 -> 0.026701745 | F7: =F6/E6-1 -> 0.027566549 | G7: =G6/F6-1 -> 0.028397539
A8: EBIT Margin | B8: =Assumptions!D7 -> 0.037003947 | C8: =Assumptions!B20 -> 0.22 | D8: =Assumptions!C20 -> 0.22 | E8: =Assumptions!D20 -> 0.2225 | F8: =Assumptions!E20 -> 0.225 | G8: =Assumptions!F20 -> 0.225
A9: Operating Income (EBIT) | B9: =Data!E7 -> 149.52 | C9: =C6*C8 -> 902.51633 | D9: =D6*D8 -> 925.01542 | E9: =E6*E8 -> 960.50716 | F9: =F6*F8 -> 998.07475 | G9: =G6*G8 -> 1026.4176
A11: 2025 Asset Impairment | B11: =Assumptions!B41 -> 738.1
A12: 2025 Impairment-Adjusted EBIT | B12: =B11+B9 -> 887.62
A14: Note: 2025 operating income includes a $738.1M impairment charge. Excluding this charge, EBIT was $887.6M, represening a 21.97% operating margin.

Sheet FCF & DCF
A1: Crocs Inc. -- Free Cash Flow & DCF Valuation
A2: USD Millions ($M)
B4: 2025 | C4: 2026 | D4: 2027 | E4: 2028 | F4: 2029 | G4: 2030
A6: Operating Income (EBIT) | B6: ='Income Statement'!B9 -> 149.52 | C6: ='Income Statement'!C9 -> 902.51633 | D6: ='Income Statement'!D9 -> 925.01542 | E6: ='Income Statement'!E9 -> 960.50716 | F6: ='Income Statement'!F9 -> 998.07475 | G6: ='Income Statement'!G9 -> 1026.4176
A7: Tax Rate | B7: =Assumptions!D8 -> 2.1126336 | C7: =Assumptions!B21 -> 0.23 | D7: =Assumptions!C21 -> 0.23 | E7: =Assumptions!D21 -> 0.23 | F7: =Assumptions!E21 -> 0.23 | G7: =Assumptions!F21 -> 0.23
A8: NOPAT | B8: - | C8: =C6*(1-C7) -> 694.93758 | D8: =D6*(1-D7) -> 712.26187 | E8: =E6*(1-E7) -> 739.59051 | F8: =F6*(1-F7) -> 768.51755 | G8: =G6*(1-G7) -> 790.34156
A10: Depreciation & Amortization | B10: =Data!E12 -> 79.28 | C10: =Assumptions!C33*Assumptions!B22 -> 80.490532 | D10: =Assumptions!D33*Assumptions!C22 -> 82.497103 | E10: =Assumptions!E33*Assumptions!D22 -> 84.69992 | F10: =Assumptions!F33*Assumptions!E22 -> 87.034804 | G10: =Assumptions!G33*Assumptions!F22 -> 89.506379
A11: Capital Expenditures | B11: =Data!E13 -> -51.23 | C11: =Assumptions!C33*Assumptions!B23 -> -75 | D11: =Assumptions!D33*Assumptions!C23 -> -79.887695 | E11: =Assumptions!E33*Assumptions!D23 -> -86.337722 | F11: =Assumptions!F33*Assumptions!E23 -> -90.935699 | G11: =Assumptions!G33*Assumptions!F23 -> -95.798977
A12: Net Working Capital | B12: =Data!E37 -> 155.698 | C12: ='Income Statement'!C6*Assumptions!B24 -> 141.42579 | D12: ='Income Statement'!D6*Assumptions!C24 -> 144.95143 | E12: ='Income Statement'!E6*Assumptions!D24 -> 148.82189 | F12: ='Income Statement'!F6*Assumptions!E24 -> 152.92439 | G12: ='Income Statement'!G6*Assumptions!F24 -> 157.26707
A13: Changes in NWC | B13: - | C13: =C12-B12 -> -14.272214 | D13: =D12-C12 -> 3.5256433 | E13: =E12-D12 -> 3.870456 | F13: =F12-E12 -> 4.1025058 | G13: =G12-F12 -> 4.3426764
A15: Free Cash Flow to Firm (FCFF) | C15: =C8+C10+C11-C13 -> 714.70032 | D15: =D8+D10+D11-D13 -> 711.34564 | E15: =E8+E10+E11-E13 -> 734.08225 | F15: =F8+F10+F11-F13 -> 760.51415 | G15: =G8+G10+G11-G13 -> 779.70629
A17: DCF Valuation
A19: Discount Period | B19: 0 | C19: 1 | D19: 2 | E19: 3 | F19: 4 | G19: 5
A20: Discount Factor | B20: =1/(1+$B$23)^B19 -> 1 | C20: =1/(1+$B$23)^C19 -> 0.90175785 | D20: =1/(1+$B$23)^D19 -> 0.81316723 | E20: =1/(1+$B$23)^E19 -> 0.73327993 | F20: =1/(1+$B$23)^F19 -> 0.66124094 | G20: =1/(1+$B$23)^G19 -> 0.59627921
A21: Present Value of FCFF | B21: - | C21: =C15*C20 -> 644.48663 | D21: =D15*D20 -> 578.44296 | E21: =E15*E20 -> 538.28779 | F21: =F15*F20 -> 502.88309 | G21: =G15*G20 -> 464.92265
A23: Discount Rate (WACC) | B23: =WACC!B30 -> 0.10894515
A25: Total PV of Forecasted FCFF | B25: =SUM(C21:G21) -> 2729.0231
A27: Terminal Value Calculation
A29: Perpetual Growth Rate | B29: 0.025
A30: Terminal Value (2030) | B30: =G15*(1+B29)/(B23-B29) -> 9520.4896
A31: PV of Terminal Value | B31: =B30/(1+B23)^5 -> 5676.87
A33: Enterprise Value ($M) | B33: =B31+B25 -> 8405.8931
A35: Equity Value Calculation
A37: Total Interest-Bearing Debt ($M) | B37: =WACC!B14 -> 1262
A38: Cash & Cash Equivalents ($M) | B38: =Data!E16 -> 130.35
A40: Implied Equity Value ($M) | B40: =B33-B37+B38 -> 7274.2431
A42: Shares Outstanding (Millions) | B42: =WACC!B24 -> 50.2
A44: Implied Share Price | B44: =B40/B42 -> 144.90524
A46: Historical Share Price -- December 2025 ($) | B46: =WACC!B23 -> 85.52
A47: Implied Upside / Downside | B47: =B44/B46-1 -> 0.69440179
A49: Terminal Valuation Cross-Check
A51: 2030 EBITDA ($M) | B51: =G6+G10 -> 1115.924
A52: Implied Terminal EV/EBITDA | B52: =B30/B51 -> 8.5314857
A54: Note: The unusually high 2025 effective tax rate reflects reported results. Forecasted cash flows use a normalized 23% tax assumption

Sheet WACC
A1: Crocs Inc -- WACC Calculation
A2: USD Millions ($M), unless otherwise noted
A4: Cost of Equity
A6: Risk-Free Rate | B6: 0.0479
A7: Equity Beta | B7: 1.56
A8: Equity Risk Premium | B8: 0.05
A9: Cost of Equity | B9: =B6+(B7*B8) -> 0.1259
A11: Cost of Debt
A13: 2024 Total Borrowings ($M) | B13: 1390
A14: 2025 Total Borrowings ($M) | B14: 1262
A15: 2025 Interest Expense ($M) | B15: 88.287
A16: Average Interest Bearing Debt ($M) | B16: =AVERAGE(B13,B14) -> 1326
A17: Pre-Tax Cost of Debt | B17: =B15/B16 -> 0.066581448
A18: Tax Rate | B18: =Assumptions!B21 -> 0.23
A19: After-Tax Cost of Debt | B19: =B17*(1-B18) -> 0.051267715
A21: Capital Structure
A23: Share Price ($) | B23: 85.52
A24: Shares Outstanding (Millions) | B24: 50.2
A25: Market Capitalization ($M) | B25: =B23*B24 -> 4293.104
A26: Total Capital ($M) | B26: =B25+B14 -> 5555.104
A27: Equity Weight | B27: =B25/B26 -> 0.77282153
A28: Debt Weight | B28: =B14/B26 -> 0.22717847
A30: Weighted Average Cost of Capital (WACC) | B30: =(B27*B9)+(B28*B19) -> 0.10894515
A32: Note: Pre-tax cost of debt is estimated using FY2025 interest expense divided by average FY2024-FY2025 interest-bearing borrowings.

Sheet Sensitivity Analysis
A1: Crocs Inc. -- DCF Sensitivity Analysis
A4: WACC vs. Perpetual Growth Rate
C6: Perpetual Growth Rate
B7: WACC
B8: ='FCF & DCF'!B44 -> 144.90524 | C8: 0.015 | D8: 0.02 | E8: 0.025 | F8: 0.03 | G8: 0.035
B9: 0.0989 | C9: 150.50584 | D9: 158.55083 | E9: 167.68445 | F9: 178.14371 | G9: 190.23979
B10: 0.1039 | C10: 140.70908 | D10: 147.72064 | E10: 155.62087 | F10: 164.59013 | G10: 174.86118
B11: 0.1089 | C11: 131.95685 | D11: 138.10947 | E11: 144.99543 | F11: 152.75412 | G11: 161.56271
B12: 0.1139 | C12: 124.09069 | D12: 129.52257 | E12: 135.56547 | F12: 142.32861 | G12: 149.94894
B13: 0.1189 | C13: 116.98265 | D13: 121.80457 | E13: 127.14001 | F13: 133.07562 | G13: 139.71868
A16: Note: Sensitivity analysis illustrates changes in implied share price across WACC and perpetual growth assumptions.

Sheet Valuation Summary
A1: Crocs Inc. -- DCF Valuation Summary
A2: 2026-Informed Valuation | FY2025 Financial Base
A4: Valuation Overview
A6: Implied Share Price | B6: ='FCF & DCF'!B44 -> 144.90524
A7: Historical Reference Price (Dec. 2025) | B7: ='FCF & DCF'!B46 -> 85.52
A8: Implied Upside vs. Historical Price | B8: ='FCF & DCF'!B47 -> 0.69440179
A11: Key Valuation Assumptions
A13: Weighted Average Cost of Capital | B13: ='FCF & DCF'!B23 -> 0.10894515
A14: Perptual Growth Rate | B14: ='FCF & DCF'!B29 -> 0.025
A15: 2030 EBIT Margin | B15: =Assumptions!F20 -> 0.225
A16: 2030 Revenue ($M) | B16: ='Income Statement'!G6 -> 4561.8561
A17: Terminal EV/EBITDA | B17: ='FCF & DCF'!B52 -> 8.5314857
A20: Valuation Conclusion
A21: The DCF analysis estimates Croc's estimated intrinsic value at $144.91 per share, based on a 10.89% WACC and a 2.50% perpetual growth rate.
A22: The forecast assumes modest revenue growth, operating margins stabilizing at 22.5%, and gradually increasing capital expenditures through 2030. Under these assumptions, the model suggests 69.44% upside compared with Crocs' December 2025 share price of $85.52.
A23: While the results suggest potential undervaluation, the valuation depends on Crocs maintaining profitability and generating consistent free cash flow. The analysis also incorporates 2026 guidance, so the upside relative to the historical share price should not be viewed as a current investment return.
A25: Note: Valuation uses FY2025 financails as the base and incorporates information from 2026. The implied upside is measured against the December 2025 share price, not the current market price.
